[
 {
  "Error": {},
  "Frames": [
   {
    "Time": 132,
    "Turn": 0
   },
   {
    "Commands": [
     {
      "angle": 224,
      "magnitude": 7,
      "owner": 0,
      "queue_number": 0,
      "shipId": 2,
      "type": "thrust"
     },
     {
      "angle": 208,
      "magnitude": 7,
      "owner": 0,
      "queue_number": 0,
      "shipId": 1,
      "type": "thrust"
     },
     {
      "angle": 217,
      "magnitude": 7,
      "owner": 0,
      "queue_number": 0,
      "shipId": 0,
      "type": "thrust"
     }
    ],
    "Planets": null,
    "Ships": [
     {
      "cooldown": 0,
      "docking": {
       "status": "undocked"
      },
      "health": 255,
      "id": 2,
      "owner": 0,
      "vel_x": 0.0,
      "vel_y": 0.0,
      "x": 114.96462139762944,
      "y": 38.137391406787017
     },
     {
      "cooldown": 0,
      "docking": {
       "status": "undocked"
      },
      "health": 255,
      "id": 1,
      "owner": 0,
      "vel_x": 0.0,
      "vel_y": 0.0,
      "x": 113.81936684998752,
      "y": 33.713699060498762
     },
     {
      "cooldown": 0,
      "docking": {
       "status": "undocked"
      },
      "health": 255,
      "id": 0,
      "owner": 0,
      "vel_x": 0.0,
      "vel_y": 0.0,
      "x": 114.40955142966895,
      "y": 35.787294837935661
     }
    ],
    "Time": 1,
    "Turn": 1
   }
  ],
  "PlayerID": 0,
  "PlayerName": "harrypotter0"
 },
 {
  "Error": {
   "Message": "ERRORED! Got Exception (if any): ERROR: Bot #1: Received invalid character 'Traceback (most recent call last):T'. (at character 1.)\nInput received from bot:\nTraceback (most recent call last):\n^; Response received (if any): Traceback (most recent call last):  File \"MyBot.py\", line 14, in <module>    model = load_model('model_checkpoint_128_batch_10_epochs.h5')  File \"/usr/local/lib/python3.5/dist-packages/keras/models.py\", line 234, in load_model    with h5py.File(filepath, mode='r') as f:  File \"/usr/local/lib/python3.5/dist-packages/h5py/_hl/files.py\", line 269, in __init__    fid = make_fid(name, mode, userblock_size, fapl, swmr=swmr)  File \"/usr/local/lib/python3.5/dist-packages/h5py/_hl/files.py\", line 99, in make_fid    fid = h5f.open(name, flags, fapl=fapl)  File \"h5py/_objects.pyx\", line 54, in h5py._objects.with_phil.wrapper  File \"h5py/_objects.pyx\", line 55, in h5py._objects.with_phil.wrapper  File \"h5py/h5f.pyx\", line 78, in h5py.h5f.openOSError: Unable to open file (unable to open file: name = 'model_checkpoint_128_batch_10_epochs.h5', errno = 2, error message = 'No such file or directory', flags = 0, o_flags = 0)",
   "Turn": 1
  },
  "Frames": [
   {
    "Time": 12579,
    "Turn": 0
   },
   {
    "Time": 295
   }
  ],
  "PlayerID": 1,
  "PlayerName": "Using TensorFlow backend."
 }
]
